Workbook

Sheet System_Playbook
A1: HSTS - HALAL SWING TRADING SYSTEM PLAYBOOK
A3: 1. SYSTEM OVERVIEW
A4: System Type | B4: Rule-based quantitative Swing Trading system optimized for momentum setups.
A5: Asset Class | B5: Indian Equities listed on NSE and BSE.
A6: Target Universe | B6: Sharia-compliant stocks with high liquidity (Market Cap > ₹500 Cr, Average Daily Volume > 100,000).
A7: Trading Regime | B7: Adaptive momentum filters powered by custom trend, volatility, volume, and levels weights.
A9: 2. SHARIA COMPLIANCE RULES (AAOIFI STANDARDS)
A10: Sector Exclusions | B10: Conventional Financial Services (Banks, Credit Services, Insurance), Tobacco, Alcohol, Brewers/Wineries, Gambling.
A11: Debt Ratio Limit | B11: Total Long Term & Short Term Debt / Total Assets must be strictly less than 33%.
A12: Cash Ratio Limit | B12: Cash And Cash Equivalents & Short Term Investments / Total Assets must be strictly less than 33%.
A13: Receivables Ratio | B13: Net Receivables / Total Assets must be strictly less than 49%.
A14: Non-Permissible Income | B14: Interest and Haram non-operating income / Total Revenue must be strictly less than 5%.
A16: 3. RISK & POSITION SIZING CONTROLS
A17: Capital Control | B17: Position sizing is dynamically calculated based on the actual Capital Available for Trading in this journal.
A18: Allocation Cap | B18: Maximum capital allocated per trade is strictly capped at 20% of your total available account balance.
A19: Stop Loss (SL) | B19: Calculated dynamically using volatility (ATR / 200 EMA bounds) to guarantee downside protection.
A20: Target Price (T1) | B20: Calculated using volatility metrics to target a minimum Risk-to-Reward ratio of 1:2.0.
A21: Market Regime Filter | B21: Bullish: Nifty 50 > 200 EMA (Trades permitted). Bearish: Nifty 50 < 200 EMA (Long entries strictly skipped).
A23: 4. SYSTEM EXECUTION COMMANDS
A24: Allocation Cap | B24: State-dependent: 20% max in State 1 (Macro Bullish); 10% max in State 2 (Bear Relief Rally) & State 3 (Capitulation Bottom); 0% in State 4 (Cash Only).
A25: EOD Sync | B25: Run: py main.py sync-zerodha-orders (Auto-syncs filled orders from Zerodha Kite, updates Ledger and Capital sheet)
A26: BSE Scan Expansion | B26: Run: py scratch/scan_all_bse.py (Scans BSE equities to expand the Sharia-compliant universe)
A27: Market Regime Filter | B27: Adaptive 4-State Engine: State 1 (Nifty > 200 EMA); State 2 (Nifty < 200 EMA, Nifty > 20 EMA, Breadth > 40%); State 3 (Nifty < 200 EMA, RSI <= 35); State 4 (All other Bearish states).
A28: Broker Integration | B28: Uses custom Zerodha Web Adapter (totp_secret & enctoken verification) to execute zero-cost trades without subscription.
A42: 5. TARGET UNIVERSE & LIQUIDITY FILTERS
A43: Total Listed Equities | B43: 7,500+ stocks across NSE and BSE combined.
A44: Sharia-Compliant | B44: 2,000+ stocks pass business and financial ratio exclusions (approx. 30-35% of Indian market).
A45: HSTS Filtered Universe | B45: 545 stocks verified as both Sharia-compliant and highly liquid for swing trading.
A46: Liquidity Pre-Filter | B46: Market Capitalization > INR 500 Crore AND Average Daily Volume > 100,000 shares.
A47: Protection Rationale | B47: Filters out volatile micro-caps and penny stocks, minimizing execution slippage and preventing lower-circuit lock-ins.

Sheet Dashboard
A1: HSTS v1.0 Trading Dashboard
A2: Last updated on : 2026-10-26 17:31:08
A3: Metric | B3: Value | D3: Stock | E3: Qty | F3: Purchase Price | G3: Current Price | H3: Current Value | I3: P&L Amount | J3: P&L % | K3: Holding % | L3: Target Reach | M3: Holding %
A4: Global Portfolio Metrics | D4: CLEAN | E4: 4 | F4: 806.25 | G4: 737.25 | H4: =E4*G4 | I4: =H4-(E4*F4) | J4: =IF(F4>0, I4/(E4*F4), 0) | K4: =H4/H14 | L4: 0.21380405 | M4: =I4/$B$11 | O4: CLEAN (4 Qty, ₹3,225) | P4: 3225 | AA4: CLEAN (4 Qty, ₹3,225) | AB4: 3225
A5: Total Net Capital Deposited | B5: =SUMIF(Capital!B:B, "DEPOSIT", Capital!C:C) | D5: OIL | E5: 4 | F5: 473 | G5: 454.89999 | H5: =E5*G5 | I5: =H5-(E5*F5) | J5: =IF(F5>0, I5/(E5*F5), 0) | K5: =H5/H14 | L5: 0.038277512 | M5: =I5/$B$11 | O5: OIL (4 Qty, ₹1,892) | P5: 1892 | AA5: OIL (4 Qty, ₹1,892) | AB5: 1892
A6: Lifetime Realized PnL | B6: =SUM(Ledger!M:M) | D6: JAIBALAJI | E6: 8 | F6: 68.87 | G6: 62.900002 | H6: =E6*G6 | I6: =H6-(E6*F6) | J6: =IF(F6>0, I6/(E6*F6), 0) | K6: =H6/H14 | L6: -0.42400002 | M6: =I6/$B$11 | O6: JAIBALAJI (8 Qty, ₹551) | P6: 550.96 | AA6: JAIBALAJI (8 Qty, ₹551) | AB6: 550.96
A7: Lifetime Realized P/L Percentage | B7: =B6/B5 | D7: IOLCP | E7: 10 | F7: 166.02 | G7: 167.98 | H7: =E7*G7 | I7: =H7-(E7*F7) | J7: =IF(F7>0, I7/(E7*F7), 0) | K7: =H7/H14 | L7: 0.10968362 | M7: =I7/$B$11 | O7: IOLCP (10 Qty, ₹1,660) | P7: 1660.2 | AA7: IOLCP (10 Qty, ₹1,660) | AB7: 1660.2
A8: Current Total Portfolio Value | B8: =B13+B12 | D8: HAPPSTMNDS | E8: 3 | F8: 426.8 | G8: 300.14999 | H8: =E8*G8 | I8: =H8-(E8*F8) | J8: =IF(F8>0, I8/(E8*F8), 0) | K8: =H8/H14 | L8: 0.24248617 | M8: =I8/$B$11 | O8: BHARATSE (6 Qty, ₹1,472) | P8: 1471.5 | AA8: HAPPSTMNDS (3 Qty, ₹1,280) | AB8: 1280.4
A9: Total Number of Trades | B9: =COUNTIF(Ledger!N:N, "WIN") + COUNTIF(Ledger!N:N, "LOSS") + COUNTIF(Ledger!N:N, "OPEN") | D9: ZEEMEDIA | E9: 150 | F9: 9.7 | G9: 6.6799998 | H9: =E9*G9 | I9: =H9-(E9*F9) | J9: =IF(F9>0, I9/(E9*F9), 0) | K9: =H9/H14 | L9: -0.060377337 | M9: =I9/$B$11 | O9: HAPPSTMNDS (3 Qty, ₹1,280) | P9: 1280.4 | AA9: ZEEMEDIA (150 Qty, ₹1,455) | AB9: 1455
A10: Winning Percentage of Trades | B10: =IF((COUNTIF(Ledger!N:N, "WIN")+COUNTIF(Ledger!N:N, "LOSS"))>0, COUNTIF(Ledger!N:N, "WIN")/(COUNTIF(Ledger!N:N, "WIN")+COUNTIF(Ledger!N:N, "LOSS")), 0) | D10: GAYAPROJ-BE | E10: 100 | F10: 21.8 | G10: 21.8 | H10: =E10*G10 | I10: =H10-(E10*F10) | J10: =IF(F10>0, I10/(E10*F10), 0) | K10: =H10/H14 | L10: 0 | M10: =I10/$B$11 | O10: ZEEMEDIA (150 Qty, ₹1,455) | P10: 1455 | AA10: GAYAPROJ-BE (100 Qty, ₹2,180) | AB10: 2180
A11: Capital Deployed in Open Trades | B11: =SUMPRODUCT((Ledger!N2:N5000="OPEN")*(Ledger!E2:E5000)*(Ledger!D2:D5000)) | D11: THELEELA | E11: 4 | F11: 539.3 | G11: 582.95001 | H11: =E11*G11 | I11: =H11-(E11*F11) | J11: =IF(F11>0, I11/(E11*F11), 0) | K11: =H11/H14 | L11: 0.22143152 | M11: =I11/$B$11 | O11: GAYAPROJ-BE (100 Qty, ₹2,180) | P11: 2180 | AA11: THELEELA (4 Qty, ₹2,157) | AB11: 2157.2
A12: Current Value of Active Trades | B12: 17397.35 | D12: KFINTECH | E12: 2 | F12: 963 | G12: 829 | H12: =E12*G12 | I12: =H12-(E12*F12) | J12: =IF(F12>0, I12/(E12*F12), 0) | K12: =H12/H14 | L12: 0.13749596 | M12: =I12/$B$11 | O12: THELEELA (4 Qty, ₹2,157) | P12: 2157.2 | AA12: KFINTECH (2 Qty, ₹1,926) | AB12: 1926
A13: Capital Available for Trading | B13: =B5 - SUMIF(Capital!B:B, "WITHDRAWAL", Capital!C:C) + B6 - B11 | D13: BOROLTD | E13: 10 | F13: 258 | G13: 237.35001 | H13: =E13*G13 | I13: =H13-(E13*F13) | J13: =IF(F13>0, I13/(E13*F13), 0) | K13: =H13/H14 | L13: -0.10282658 | M13: =I13/$B$11 | AA13: BOROLTD (10 Qty, ₹2,580) | AB13: 2580
A14: Total Wins | B14: =COUNTIF(Ledger!N:N, "WIN") | D14: Total Portfolio | H14: =SUM(H4:H13) | I14: =SUM(I4:I13) | J14: =IF((H14-I14)>0, I14/(H14-I14), 0) | K14: =SUM(K4:K13)
A15: Total Losses | B15: =COUNTIF(Ledger!N:N, "LOSS")
A16: Total Taxes Paid to Zerodha | B16: =SUMIF(Capital!D:D, "*Brokerage & taxes*", Capital!C:C)
A17: Swing Trading Statistics
A18: Swing Win Rate | B18: =IF((COUNTIFS(Ledger!P:P, "SWING", Ledger!N:N, "WIN")+COUNTIFS(Ledger!P:P, "SWING", Ledger!N:N, "LOSS"))>0, COUNTIFS(Ledger!P:P, "SWING", Ledger!N:N, "WIN")/(COUNTIFS(Ledger!P:P, "SWING", Ledger!N:N, "WIN")+COUNTIFS(Ledger!P:P, "SWING", Ledger!N:N, "LOSS")), 0)
A19: Swing Realized PnL | B19: =SUMIFS(Ledger!M:M, Ledger!P:P, "SWING")
A20: Swing Completed Trades | B20: =COUNTIFS(Ledger!P:P, "SWING", Ledger!N:N, "WIN") + COUNTIFS(Ledger!P:P, "SWING", Ledger!N:N, "LOSS")
A21: Swing Active Positions | B21: =COUNTIFS(Ledger!P:P, "SWING", Ledger!N:N, "OPEN")
A22: Intraday Trading Statistics
A23: Intraday Win Rate | B23: =IF((COUNTIFS(Ledger!P:P, "INTRADAY", Ledger!N:N, "WIN")+COUNTIFS(Ledger!P:P, "INTRADAY", Ledger!N:N, "LOSS"))>0, COUNTIFS(Ledger!P:P, "INTRADAY", Ledger!N:N, "WIN")/(COUNTIFS(Ledger!P:P, "INTRADAY", Ledger!N:N, "WIN")+COUNTIFS(Ledger!P:P, "INTRADAY", Ledger!N:N, "LOSS")), 0)
A24: Intraday Realized PnL | B24: =SUMIFS(Ledger!M:M, Ledger!P:P, "INTRADAY")
A25: Intraday Completed Trades | B25: =COUNTIFS(Ledger!P:P, "INTRADAY", Ledger!N:N, "WIN") + COUNTIFS(Ledger!P:P, "INTRADAY", Ledger!N:N, "LOSS")
A26: Intraday Active Positions | B26: =COUNTIFS(Ledger!P:P, "INTRADAY", Ledger!N:N, "OPEN")
A27: Activity & Performance Metrics
A28: Average Days to Exit a Trade | B28: 23.527778
A29: Average Trades per Day | B29: 2.4
A30: Average Unique Holdings per Day | B30: 9.0428571
A31: Average Profit % per trade | B31: 0.064223361
A32: Average Loss % per trade | B32: -0.039776677
A33: Average Value per Trade | B33: 1503.3269

Sheet Ledger
A1: Symbol | B1: Name | C1: Entry Date | D1: Qty | E1: Buy Price | F1: Suggested Entry | G1: Slippage/Deviation | H1: Target Price | I1: Stop Loss | J1: Risk-to-Reward Ratio | K1: Exit Date | L1: Exit Price | M1: Realized PnL | N1: Status | O1: Notes | P1: Trade Type | Q1: Current Price | R1: Unrealized PnL | S1: Profit/Loss %
A2: SUNPHARMA | B2: SUNPHARMA | C2: 2026-07-21 | D2: 1 | E2: 1951 | F2: 1963.2 | G2: -12.199951 | H2: 2091.5434 | I2: 1899.0282 | J2: 1:2.7 | K2: 2026-07-21 | L2: 1960 | M2: =IF(OR(N2="WIN", N2="LOSS"), (L2-E2)*D2, 0) | N2: WIN | O2: Auto-synced from Zerodha account | Auto-synced sell from Zerodha account | P2: SWING | S2: =IF(N2="OPEN", IFERROR(R2/(D2*E2), 0), IF(OR(N2="WIN", N2="LOSS"), IFERROR(M2/(D2*E2), 0), 0))
A3: JSWSTEEL | B3: JSWSTEEL | C3: 2026-07-21 | D3: 1 | E3: 1266.4 | F3: 1268.1 | G3: -1.6999756 | H3: 1369.6842 | I3: 1217.3078 | J3: 1:2.1 | K3: 2026-07-21 | L3: 1267.1 | M3: =IF(OR(N3="WIN", N3="LOSS"), (L3-E3)*D3, 0) | N3: WIN | O3: Auto-synced from Zerodha account | Auto-synced sell from Zerodha account | P3: SWING | S3: =IF(N3="OPEN", IFERROR(R3/(D3*E3), 0), IF(OR(N3="WIN", N3="LOSS"), IFERROR(M3/(D3*E3), 0), 0))
A4: TECHM | B4: TECHM | C4: 2026-07-21 | D4: 1 | E4: 1589.1 | F4: 1582.7 | G4: 6.4000488 | H4: 1785.9687 | I4: 1481.0656 | J4: 1:1.8 | K4: 2026-07-21 | L4: 1575 | M4: =IF(OR(N4="WIN", N4="LOSS"), (L4-E4)*D4, 0) | N4: LOSS | O4: Auto-synced from Zerodha account | Auto-synced sell from Zerodha account | P4: SWING | S4: =IF(N4="OPEN", IFERROR(R4/(D4*E4), 0), IF(OR(N4="WIN", N4="LOSS"), IFERROR(M4/(D4*E4), 0), 0))
A5: SONACOMS | B5: SONACOMS | C5: 2026-07-22 | D5: 2 | E5: 734.7 | F5: 730.45001 | G5: 4.2499878 | H5: 800.57862 | I5: 695.38571 | J5: 1:1.7 | K5: 2026-08-05 | L5: 798.25 | M5: =IF(OR(N5="WIN", N5="LOSS"), (L5-E5)*D5, 0) | N5: WIN | O5: Auto-synced from Zerodha account | [2026-07-28] State 4 (Cash Only): Hold position, maintain pre-set stop-loss, do not average down. | Auto-synced sell from Zerodha account | P5: SWING | S5: =IF(N5="OPEN", IFERROR(R5/(D5*E5), 0), IF(OR(N5="WIN", N5="LOSS"), IFERROR(M5/(D5*E5), 0), 0))
A6: JSWSTEEL | B6: JSW Steel Limited | C6: 2026-07-22 | D6: 1 | E6: 1265.1 | F6: 1265.1 | G6: 0 | H6: 1368.16 | I6: 1217.31 | J6: 1:2.1 | K6: 2026-08-13 | L6: 1269.1 | M6: =IF(OR(N6="WIN", N6="LOSS"), (L6-E6)*D6, 0) | N6: WIN | O6: Auto-synced from Zerodha account | [2026-07-28] State 4 (Cash Only): Hold position, maintain pre-set stop-loss, do not average down. | Auto-synced sell from Zerodha account | P6: SWING | S6: =IF(N6="OPEN", IFERROR(R6/(D6*E6), 0), IF(OR(N6="WIN", N6="LOSS"), IFERROR(M6/(D6*E6), 0), 0))
A7: TECHM | B7: TECHM | C7: 2026-07-27 | D7: 1 | E7: 1579 | F7: 1593.9 | G7: -14.900024 | H7: 1773.6429 | I7: 1504.0286 | J7: 1:2.6 | K7: 2026-08-13 | L7: 1634.7 | M7: =IF(OR(N7="WIN", N7="LOSS"), (L7-E7)*D7, 0) | N7: WIN | O7: Auto-synced from Zerodha account | [2026-07-28] State 4 (Cash Only): Hold position, maintain pre-set stop-loss, do not average down. | Auto-synced sell from Zerodha account | P7: SWING | S7: =IF(N7="OPEN", IFERROR(R7/(D7*E7), 0), IF(OR(N7="WIN", N7="LOSS"), IFERROR(M7/(D7*E7), 0), 0))
A8: BERGEPAINT | B8: Berger Paints India Limited | C8: 2026-07-31 | D8: 2 | E8: 519.13 | F8: 521.35 | G8: -2.22 | H8: 574.85 | I8: 494.6 | J8: 1:2.0 | K8: 2026-08-12 | L8: 561.2 | M8: =IF(OR(N8="WIN", N8="LOSS"), (L8-E8)*D8, 0) | N8: WIN | O8: Auto-synced from Zerodha holdings | Auto-synced sell from Zerodha account | P8: SWING | S8: =IF(N8="OPEN", IFERROR(R8/(D8*E8), 0), IF(OR(N8="WIN", N8="LOSS"), IFERROR(M8/(D8*E8), 0), 0))
A9: ADVANCE | B9: Advanced Enzyme Technologies Limited | C9: 2026-08-03 | D9: 4 | E9: 127.8 | F9: 125.01 | G9: 2.79 | H9: 145.56 | I9: 114.74 | J9: 1:2.0 | K9: 2026-08-12 | L9: 118.2425 | M9: =IF(OR(N9="WIN", N9="LOSS"), (L9-E9)*D9, 0) | N9: LOSS | O9: Buy actual fill price matching Zerodha (corrected from 125.01) | Auto-synced sell from Zerodha account | P9: SWING | S9: =IF(N9="OPEN", IFERROR(R9/(D9*E9), 0), IF(OR(N9="WIN", N9="LOSS"), IFERROR(M9/(D9*E9), 0), 0))
A10: NESTLEIND | B10: NESTLEIND | C10: 2026-08-04 | D10: 1 | E10: 1530 | F10: 1530 | G10: 0 | H10: 1549.8 | I10: 1520.1 | J10: 1:2.0 | K10: 2026-08-04 | L10: 1520.1 | M10: =IF(OR(N10="WIN", N10="LOSS"), (L10-E10)*D10, 0) | N10: LOSS | O10: Intraday placement. GTT Trigger: 330204955 | Position closed via Stop-Loss GTT trigger. Actual Buy Filled at INR 1523.00 | P10: INTRADAY | S10: =IF(N10="OPEN", IFERROR(R10/(D10*E10), 0), IF(OR(N10="WIN", N10="LOSS"), IFERROR(M10/(D10*E10), 0), 0))
A11: PIDILITIND | B11: PIDILITIND | C11: 2026-08-04 | D11: 1 | E11: 1642.5 | F11: 1642.5 | G11: 0 | H11: 1658.5 | I11: 1634.5 | J11: 1:2.0 | K11: 2026-08-04 | L11: 1634.5 | M11: =IF(OR(N11="WIN", N11="LOSS"), (L11-E11)*D11, 0) | N11: LOSS | O11: Intraday placement. GTT Trigger: 330204926 | Position closed via Stop-Loss GTT trigger. | P11: INTRADAY | S11: =IF(N11="OPEN", IFERROR(R11/(D11*E11), 0), IF(OR(N11="WIN", N11="LOSS"), IFERROR(M11/(D11*E11), 0), 0))
A12: VISAKAIND | B12: VISAKAIND | C12: 2026-08-05 | D12: 8 | E12: 86.99 | F12: 86.99 | G12: 0 | H12: 101.83 | I12: 79.57 | J12: 1:2.0 | K12: 2026-08-10 | L12: 103.24 | M12: =IF(OR(N12="WIN", N12="LOSS"), (L12-E12)*D12, 0) | N12: WIN | O12: Swing AMO placement. GTT Trigger: 330406766 | Auto-synced sell from Zerodha account | P12: SWING | S12: =IF(N12="OPEN", IFERROR(R12/(D12*E12), 0), IF(OR(N12="WIN", N12="LOSS"), IFERROR(M12/(D12*E12), 0), 0))
A13: EXCELSOFT | B13: EXCELSOFT | C13: 2026-08-05 | D13: 8 | E13: 82.5 | F13: 82.5 | G13: 0 | H13: 93.81 | I13: 77.58 | J13: 1:2.0 | K13: 2026-08-10 | L13: 77.58 | M13: =IF(OR(N13="WIN", N13="LOSS"), (L13-E13)*D13, 0) | N13: LOSS | O13: Swing AMO placement. GTT Trigger: 330406774 | Auto-synced sell from Zerodha account | P13: SWING | S13: =IF(N13="OPEN", IFERROR(R13/(D13*E13), 0), IF(OR(N13="WIN", N13="LOSS"), IFERROR(M13/(D13*E13), 0), 0))
... A21: BEL | B21: BEL | C21: 2026-08-12 | D21: 5 | E21: 405.85 | F21: 401.35001 | G21: 4.4999939 | H21: 429.26429 | I21: 387.39287 | J21: 1:1.3 | K21: 2026-08-12 | L21: 399.4 | M21: =IF(OR(N21="WIN", N21="LOSS"), (L21-E21)*D21, 0) | N21: LOSS | O21: Auto-synced from Zerodha account | Auto-synced sell from Zerodha account | P21: SWING | S21: =IF(N21="OPEN", IFERROR(R21/(D21*E21), 0), IF(OR(N21="WIN", N21="LOSS"), IFERROR(M21/(D21*E21), 0), 0))
A22: CLEAN | B22: CLEAN | C22: 2026-08-12 | D22: 4 | E22: 806.25 | F22: 802 | G22: 4.25 | H22: 896.28571 | I22: 754.85714 | J22: 1:1.8 | M22: =IF(OR(N22="WIN", N22="LOSS"), (L22-E22)*D22, 0) | N22: OPEN | O22: Auto-synced from Zerodha account | P22: SWING | Q22: 825.5 | R22: 77 | S22: =IF(N22="OPEN", IFERROR(R22/(D22*E22), 0), IF(OR(N22="WIN", N22="LOSS"), IFERROR(M22/(D22*E22), 0), 0))
A23: MRPL | B23: MRPL | C23: 2026-08-13 | D23: 10 | E23: 174.7 | F23: 181.14 | G23: -6.44 | H23: 213.09 | I23: 165.17 | J23: 1:2.0 | K23: 2026-08-20 | L23: 165.15 | M23: =IF(OR(N23="WIN", N23="LOSS"), (L23-E23)*D23, 0) | N23: LOSS | O23: Auto-added SWING via AI recommendation. SL: 165.17, TP: 213.09 (Orders pending 5:30 AM due to Zerodha AMO maintenance). | P23: SWING | S23: =IF(N23="OPEN", IFERROR(R23/(D23*E23), 0), IF(OR(N23="WIN", N23="LOSS"), IFERROR(M23/(D23*E23), 0), 0))
A24: LENSKART | B24: LENSKART | C24: 2026-08-13 | D24: 4 | E24: 605 | F24: 589.2 | G24: 15.8 | H24: 646.81 | I24: 560.39 | J24: 1:2.0 | K24: 2026-08-20 | L24: 646.8 | M24: =IF(OR(N24="WIN", N24="LOSS"), (L24-E24)*D24, 0) | N24: WIN | O24: Auto-added SWING via AI recommendation. SL: 560.39, TP: 646.81 (Orders pending 5:30 AM due to Zerodha AMO maintenance). | P24: SWING | S24: =IF(N24="OPEN", IFERROR(R24/(D24*E24), 0), IF(OR(N24="WIN", N24="LOSS"), IFERROR(M24/(D24*E24), 0), 0))
A25: OIL | B25: OIL | C25: 2026-08-13 | D25: 4 | E25: 473 | F25: 470.35 | G25: 2.65 | H25: 525.25 | I25: 442.9 | J25: 1:2.0 | M25: =IF(OR(N25="WIN", N25="LOSS"), (L25-E25)*D25, 0) | N25: OPEN | O25: Auto-added SWING via AI recommendation. SL: 442.9, TP: 525.25 (Orders pending 5:30 AM due to Zerodha AMO maintenance). | P25: SWING | Q25: 475 | R25: 8 | S25: =IF(N25="OPEN", IFERROR(R25/(D25*E25), 0), IF(OR(N25="WIN", N25="LOSS"), IFERROR(M25/(D25*E25), 0), 0))
A26: AARTIIND | B26: AARTIIND | C26: 2026-08-13 | D26: 4 | E26: 536 | F26: 532.3 | G26: 3.7 | H26: 562.65 | I26: 517.1 | J26: 1:2.0 | K26: 2026-08-14 | L26: 539.25 | M26: =IF(OR(N26="WIN", N26="LOSS"), (L26-E26)*D26, 0) | N26: WIN | O26: Auto-added INTRADAY via AI recommendation. SL: 517.1, TP: 562.65 (Orders pending 5:30 AM due to Zerodha AMO maintenance). | Auto-synced from Zerodha account | Auto-synced sell from Zerodha account | P26: INTRADAY | S26: =IF(N26="OPEN", IFERROR(R26/(D26*E26), 0), IF(OR(N26="WIN", N26="LOSS"), IFERROR(M26/(D26*E26), 0), 0))
A27: SCHNEIDER | B27: SCHNEIDER | C27: 2026-08-13 | D27: 2 | E27: 1425 | F27: 1435 | G27: -10 | H27: 1502.9 | I27: 1401.05 | J27: 1:2.0 | K27: 2026-08-14 | L27: 1401 | M27: =IF(OR(N27="WIN", N27="LOSS"), (L27-E27)*D27, 0) | N27: LOSS | O27: Auto-added INTRADAY via AI recommendation. SL: 1401.05, TP: 1502.9 (Orders pending 5:30 AM due to Zerodha AMO maintenance). | Auto-synced from Zerodha account | Auto-synced sell from Zerodha account | P27: INTRADAY | S27: =IF(N27="OPEN", IFERROR(R27/(D27*E27), 0), IF(OR(N27="WIN", N27="LOSS"), IFERROR(M27/(D27*E27), 0), 0))
A28: JAIBALAJI | B28: Jai Balaji Industries Limited | C28: 2026-08-14 | D28: 8 | E28: 68.87 | F28: 68.87 | G28: 0 | H28: 81.37 | I28: 62.62 | J28: 1:2.0 | M28: =IF(OR(N28="WIN", N28="LOSS"), (L28-E28)*D28, 0) | N28: OPEN | O28: Swing trade setup. | P28: SWING | Q28: 63.57 | R28: -42.400002 | S28: =IF(N28="OPEN", IFERROR(R28/(D28*E28), 0), IF(OR(N28="WIN", N28="LOSS"), IFERROR(M28/(D28*E28), 0), 0))
A29: IOLCP | B29: IOL Chemicals and Pharmaceuticals Limited | C29: 2026-08-14 | D29: 10 | E29: 166.02 | F29: 166.02 | G29: 0 | H29: 197.93 | I29: 150.06 | J29: 1:2.0 | M29: =IF(OR(N29="WIN", N29="LOSS"), (L29-E29)*D29, 0) | N29: OPEN | O29: Swing trade setup. | P29: SWING | Q29: 169.52 | R29: 35.000043 | S29: =IF(N29="OPEN", IFERROR(R29/(D29*E29), 0), IF(OR(N29="WIN", N29="LOSS"), IFERROR(M29/(D29*E29), 0), 0))
A30: BHARATSE | B30: Bharat Seats Limited | C30: 2026-08-14 | D30: 6 | E30: 245.25 | F30: 245.25 | G30: 0 | H30: 297.64 | I30: 219.06 | J30: 1:2.0 | K30: 2026-08-21 | L30: 230.26 | M30: =IF(OR(N30="WIN", N30="LOSS"), (L30-E30)*D30, 0) | N30: LOSS | O30: Swing trade setup. | Sold manually on 2026-08-20 | P30: SWING | S30: =IF(N30="OPEN", IFERROR(R30/(D30*E30), 0), IF(OR(N30="WIN", N30="LOSS"), IFERROR(M30/(D30*E30), 0), 0))
A31: HAPPSTMNDS | B31: Happiest Minds | C31: 2026-08-18 | D31: 3 | E31: 426.8 | F31: 426.8 | G31: 0 | H31: 500 | I31: 400 | M31: =IF(OR(N31="WIN", N31="LOSS"), (L31-E31)*D31, 0) | N31: OPEN | P31: SWING | Q31: 444.54999 | R31: 53.249963 | S31: =IF(N31="OPEN", IFERROR(R31/(D31*E31), 0), IF(OR(N31="WIN", N31="LOSS"), IFERROR(M31/(D31*E31), 0), 0))
A32: ZEEMEDIA | B32: Zee Media | C32: 2026-08-18 | D32: 150 | E32: 9.7 | F32: 9.7 | G32: 0 | H32: 15 | I32: 8 | M32: =IF(OR(N32="WIN", N32="LOSS"), (L32-E32)*D32, 0) | N32: OPEN | P32: SWING | Q32: 9.3800001 | R32: -47.999983 | S32: =IF(N32="OPEN", IFERROR(R32/(D32*E32), 0), IF(OR(N32="WIN", N32="LOSS"), IFERROR(M32/(D32*E32), 0), 0))
A33: APEX | B33: Apex Frozen | C33: 2026-08-18 | D33: 3 | E33: 422.55 | F33: 422.55 | G33: 0 | H33: 500 | I33: 400 | K33: 2026-08-20 | L33: 400 | M33: =IF(OR(N33="WIN", N33="LOSS"), (L33-E33)*D33, 0) | N33: LOSS | P33: SWING | S33: =IF(N33="OPEN", IFERROR(R33/(D33*E33), 0), IF(OR(N33="WIN", N33="LOSS"), IFERROR(M33/(D33*E33), 0), 0))
A34: GAYAPROJ-BE | B34: Gayatri Projects | C34: 2026-08-18 | D34: 100 | E34: 21.8 | F34: 22.2 | G34: -0.4 | H34: 26.55 | I34: 20 | M34: =IF(OR(N34="WIN", N34="LOSS"), (L34-E34)*D34, 0) | N34: OPEN | P34: SWING | S34: =IF(N34="OPEN", IFERROR(R34/(D34*E34), 0), IF(OR(N34="WIN", N34="LOSS"), IFERROR(M34/(D34*E34), 0), 0))
A35: THELEELA | B35: THELEELA | C35: 2026-08-20 | D35: 4 | E35: 539.3 | F35: 539.3 | G35: 0 | H35: 640.46 | I35: 498.76 | J35: 1:2.5 | M35: =IF(OR(N35="WIN", N35="LOSS"), (L35-E35)*D35, 0) | N35: OPEN | O35: Manual Override (Cash Only Regime). GTT Trigger: UNKNOWN | P35: SWING | Q35: 561.70001 | R35: 89.600049 | S35: =IF(N35="OPEN", IFERROR(R35/(D35*E35), 0), IF(OR(N35="WIN", N35="LOSS"), IFERROR(M35/(D35*E35), 0), 0))
A36: KFINTECH | B36: KFin Technologies Limited | C36: 2026-08-21 | D36: 2 | E36: 963 | F36: 961 | G36: 0 | H36: 1086.64 | I36: 910.74 | J36: 1:2.5 | M36: =IF(OR(N36="WIN", N36="LOSS"), (L36-E36)*D36, 0) | N36: OPEN | O36: Swing Trade. GTT Trigger: UNKNOWN | P36: SWING | Q36: 980 | R36: 34 | S36: =IF(N36="OPEN", IFERROR(R36/(D36*E36), 0), IF(OR(N36="WIN", N36="LOSS"), IFERROR(M36/(D36*E36), 0), 0))
A37: BOROLTD | B37: Borosil Limited | C37: 2026-08-21 | D37: 10 | E37: 258 | F37: 248.11 | G37: 0 | H37: 295.15 | I37: 229.3 | J37: 1:2.5 | M37: =IF(OR(N37="WIN", N37="LOSS"), (L37-E37)*D37, 0) | N37: OPEN | O37: AMO Swing Trade | P37: SWING | Q37: 254.17999 | R37: -38.200073 | S37: =IF(N37="OPEN", IFERROR(R37/(D37*E37), 0), IF(OR(N37="WIN", N37="LOSS"), IFERROR(M37/(D37*E37), 0), 0))
M38: =IF(OR(N53="WIN", N53="LOSS"), (L53-E53)*D53, 0)
M39: =IF(OR(N54="WIN", N54="LOSS"), (L54-E54)*D54, 0)
M40: =IF(OR(N55="WIN", N55="LOSS"), (L55-E55)*D55, 0)
M41: =IF(OR(N56="WIN", N56="LOSS"), (L56-E56)*D56, 0)
M42: =IF(OR(N57="WIN", N57="LOSS"), (L57-E57)*D57, 0)
M43: =IF(OR(N58="WIN", N58="LOSS"), (L58-E58)*D58, 0)
M44: =IF(OR(N59="WIN", N59="LOSS"), (L59-E59)*D59, 0)
M45: =IF(OR(N60="WIN", N60="LOSS"), (L60-E60)*D60, 0)
M46: =IF(OR(N61="WIN", N61="LOSS"), (L61-E61)*D61, 0)
M47: =IF(OR(N62="WIN", N62="LOSS"), (L62-E62)*D62, 0)
...

Sheet Recommendations
A1: Date | B1: Symbol | C1: Name | D1: Composite Score | E1: Target Entry Price | F1: Initial Stop-Loss | G1: Profit Target | H1: Risk-to-Reward Ratio | I1: Recommended Qty | J1: Recommended Allocation | K1: Execution Status | L1: Notes
A2: 2026-07-21 | B2: JSWSTEEL | C2: JSW Steel Limited | D2: 96/100 | E2: 1267.4 | F2: 1217.5335 | G2: 1367.1331 | H2: 1:2.0 | I2: 1 | J2: 1267.4 | K2: SKIPPED_BEARISH_REGIME | L2: Scanned under BEARISH regime
A3: 2026-07-21 | B3: LUPIN | C3: Lupin Limited | D3: 96/100 | E3: 2514.8 | F3: 2414.0867 | G3: 2716.2267 | H3: 1:2.0 | I3: 0 | J3: 0 | K3: SKIPPED_BEARISH_REGIME | L3: Scanned under BEARISH regime
A4: 2026-07-21 | B4: ULTRACEMCO | C4: UltraTech Cement Limited | D4: 94/100 | E4: 12094 | F4: 11658.429 | G4: 12965.143 | H4: 1:2.0 | I4: 0 | J4: 0 | K4: SKIPPED_BEARISH_REGIME | L4: Scanned under BEARISH regime
A5: 2026-07-21 | B5: NAVINFLUOR | C5: Navin Fluorine International Limited | D5: 94/100 | E5: 7882 | F5: 7455.1429 | G5: 8735.7143 | H5: 1:2.0 | I5: 0 | J5: 0 | K5: SKIPPED_BEARISH_REGIME | L5: Scanned under BEARISH regime
A6: 2026-07-21 | B6: ERIS | C6: Eris Lifesciences Limited | D6: 94/100 | E6: 1470 | F6: 1391.3142 | G6: 1627.3715 | H6: 1:2.0 | I6: 1 | J6: 1470 | K6: SKIPPED_BEARISH_REGIME | L6: Scanned under BEARISH regime
A7: 2026-07-22 | B7: JSWSTEEL | C7: JSW Steel Limited | D7: 96/100 | E7: 1267.4 | F7: 1219.23 | G7: 1363.73 | H7: 1:2.0 | I7: 1 | J7: 1267.4 | K7: SKIPPED_BEARISH_REGIME | L7: Manual execution shift requested by user
A8: 2026-07-22 | B8: SONACOMS | C8: Sona BLW Precision Forgings Limited | D8: 92/100 | E8: 732.75 | F8: 703.5 | G8: 797.86 | H8: 1:2.0 | I8: 2 | J8: 1465.5 | K8: SKIPPED_BEARISH_REGIME | L8: Manual execution shift requested by user
A9: 2026-07-22 | B9: LUPIN | C9: Lupin Limited | D9: 96/100 | E9: 2514.8 | F9: 2417.09 | G9: 2710.23 | H9: 1:2.0 | I9: 0 | J9: 0 | K9: SKIPPED_BEARISH_REGIME | L9: Manual execution shift requested by user
A10: 2026-07-22 | B10: HAL | C10: Hindustan Aeronautics Limited | D10: 90/100 | E10: 4581.7 | F10: 4414.33 | G10: 4916.44 | H10: 1:2.0 | I10: 0 | J10: 0 | K10: SKIPPED_BEARISH_REGIME | L10: Manual execution shift requested by user
A11: 2026-07-22 | B11: SHREECEM | C11: Shree Cement Limited | D11: 92/100 | E11: 27245 | F11: 26152.92 | G11: 29429.17 | H11: 1:2.0 | I11: 0 | J11: 0 | K11: SKIPPED_BEARISH_REGIME | L11: Manual execution shift requested by user
A12: 2026-07-27 | B12: TECHM | C12: Tech Mahindra Limited | D12: 76/100 | E12: 1559.5 | F12: 1508.1 | G12: 1746.3 | H12: 1:2.0 | I12: 0 | J12: 0 | K12: PENDING | L12: Scanned under STATE 3: Capitulation Bottom
A13: 2026-07-30 | B13: BERGEPAINT | C13: Berger Paints India Limited | D13: 96/100 | E13: 521.35 | F13: 494.6 | G13: 574.85 | H13: 1:2.0 | I13: 1 | J13: 521.35 | K13: PENDING | L13: After Market Order (AMO) placed on 2026-07-30 | GTT Trigger ID: 329793870
... A490: 2026-10-26 | B490: JSWSTEEL | C490: JSW Steel Limited | D490: 100/100 | E490: 1260 | F490: 1236.35 | G490: 1319.2 | H490: 1:2.5 | I490: 0 | J490: 0 | K490: PENDING | L490: Intraday Scanner (STATE 4: Cash Only)

Sheet Capital
A1: Date | B1: Type | C1: Amount | D1: Notes
A2: 21-7-2026 | B2: DEPOSIT | C2: 10000
A3: 2026-07-22 | B3: WITHDRAWAL | C3: 1.76 | D3: Brokerage & taxes on SONACOMS BUY (2 qty @ 734.70)
A4: 2026-07-22 | B4: WITHDRAWAL | C4: 1.52 | D4: Brokerage & taxes on JSWSTEEL BUY (1 qty @ 1265.10)
A5: 2026-07-24 | B5: WITHDRAWAL | C5: 181.62 | D5: Adjustment: Brokerage & taxes on past completed trades (SUNPHARMA, JSWSTEEL, TECHM)
A6: 2026-07-27 | B6: WITHDRAWAL | C6: 1.89 | D6: Brokerage & taxes on TECHM BUY (1 qty @ 1579.00)
A7: 2026-07-31 | B7: WITHDRAWAL | C7: 1.76 | D7: Brokerage & taxes on BERGEPAINT BUY
A8: 2026-08-03 | B8: WITHDRAWAL | C8: 0.61 | D8: Brokerage & taxes on ADVANCE BUY (4 qty @ 127.80)
A9: 2026-08-03 | B9: WITHDRAWAL | C9: 0.12 | D9: Brokerage & taxes on ADVANCE BUY (1 qty @ 100.00)
A10: 2026-08-04 | B10: WITHDRAWAL | C10: 1.84 | D10: Brokerage & taxes on NESTLEIND BUY (1 qty @ 1530.00)
A11: 2026-08-04 | B11: WITHDRAWAL | C11: 1.97 | D11: Brokerage & taxes on PIDILITIND BUY (1 qty @ 1642.50)
A12: 2026-08-04 | B12: WITHDRAWAL | C12: 1.83 | D12: Brokerage & taxes on NESTLEIND SELL (1 qty @ 1520.10)
A13: 2026-08-04 | B13: WITHDRAWAL | C13: 1.96 | D13: Brokerage & taxes on PIDILITIND SELL (1 qty @ 1634.50)
A14: 2026-08-05 | B14: WITHDRAWAL | C14: 0.84 | D14: Brokerage & taxes on VISAKAIND BUY (8 qty @ 86.99)
... A1019: 2026-08-21 | B1019: WITHDRAWAL | C1019: 3.1 | D1019: Brokerage & taxes on BOROLTD BUY (10 qty @ 258.00)

Sheet Logs
A1: Timestamp | B1: Level | C1: Message
A2: 2026-07-21 12:48:41 | B2: INFO | C2: Recorded buy order: 1 shares of SUNPHARMA at 1951
A3: 2026-07-21 12:48:42 | B3: INFO | C3: Recorded buy order: 1 shares of JSWSTEEL at 1266.4
A4: 2026-07-21 12:48:42 | B4: INFO | C4: Recorded buy order: 1 shares of TECHM at 1589.1
A5: 2026-07-21 15:33:36 | B5: INFO | C5: Closed trade: SUNPHARMA exited at 1960 (WIN)
A6: 2026-07-21 15:33:37 | B6: INFO | C6: Closed trade: TECHM exited at 1575 (WIN)
A7: 2026-07-21 15:33:38 | B7: INFO | C7: Closed trade: JSWSTEEL exited at 1267.1 (WIN)
A8: 2026-07-22 11:27:23 | B8: INFO | C8: Recorded buy order: 2 shares of SONACOMS at 734.7
A9: 2026-07-22 11:27:25 | B9: INFO | C9: Recorded buy order: 1 shares of JSWSTEEL at 1265.1
A10: 2026-07-22 11:28:22 | B10: INFO | C10: Capital Transaction: WITHDRAWAL of INR 1.76 logged.
A11: 2026-07-22 11:28:24 | B11: INFO | C11: Capital Transaction: WITHDRAWAL of INR 1.52 logged.
A12: 2026-07-27 10:14:17 | B12: INFO | C12: Recorded buy order: 1 shares of TECHM at 1579
... A138: 2026-08-21 16:03:28 | B138: INFO | C138: Updated MTM prices for 9 open trades.

Sheet Paper_Trades
A1: Date | B1: Symbol | C1: Company Name | D1: Entry Price | E1: Stop Loss | F1: Target | G1: Initial Alloc | H1: Status | I1: Current Price | J1: P&L (INR) | K1: Notes
A2: 2026-07-24 | B2: SUNPHARMA | C2: Sun Pharmaceutical | D2: 1954 | E2: 1890.88 | F2: 2080.24 | G2: 2000 | H2: MONITORING | I2: 1954 | J2: 0 | K2: Paper trade for momentum score tracking (96.4/100)
A3: 2026-07-24 | B3: BAJAJ-AUTO | C3: Bajaj Auto Limited | D3: 11283.5 | E3: 10780.43 | F3: 12289.64 | G3: 2000 | H3: MONITORING | I3: 11283.5 | J3: 0 | K3: Paper trade for momentum score tracking (88.8/100)
A4: 2026-07-24 | B4: HEROMOTOCO | C4: Hero MotoCorp | D4: 5098.8 | E4: 4900.54 | F4: 5495.31 | G4: 2000 | H4: MONITORING | I4: 5098.8 | J4: 0 | K4: Paper trade for momentum score tracking (88.8/100)
A5: 2026-07-24 | B5: SIEMENS | C5: Siemens Limited | D5: 3686.3 | E5: 3491.06 | F5: 4076.79 | G5: 2000 | H5: MONITORING | I5: 3686.3 | J5: 0 | K5: Paper trade for momentum score tracking (88.2/100)
A6: 2026-07-24 | B6: HAL | C6: Hindustan Aeronautics | D6: 4592.5 | E6: 4418.04 | F6: 4941.41 | G6: 2000 | H6: MONITORING | I6: 4592.5 | J6: 0 | K6: Paper trade for momentum score tracking (85.2/100)

Sheet HelperData
A1: Date | B1: Cumulative PnL
A2: 2026-07-21 | B2: -4.4
A3: 2026-08-04 | B3: -22.3
A4: 2026-08-05 | B4: 104.8
A5: 2026-08-06 | B5: 103.85
A6: 2026-08-10 | B6: 119.64
A7: 2026-08-12 | B7: 120.95
A8: 2026-08-13 | B8: 180.65
A9: 2026-08-14 | B9: 145.65
A10: 2026-08-18 | B10: 92.89
A11: 2026-08-20 | B11: 96.94
A12: 2026-08-21 | B12: 7
